Workbook

Sheet Table 2
B2: Iteraciones | C2: Avg. | D2: Time | E2: Dev. | F2: #best
B3: =C10 -> Baseline | C3: =AVERAGEIF(K12:K128, "<>-", C12:C128) -> 153.90769 | D3: =AVERAGEIF(L12:L128, "<>-", D12:D128) -> 6.6314692 | E3: =AVERAGE(E12:E37) -> 0.0034001275 | F3: =SUMIF(K12:K128, "<>-", F12:F128) -> 14
B4: =G10 -> Gc | C4: =AVERAGEIF(K12:K128, "<>-", G12:G128) -> 154.68462 | D4: =AVERAGEIF(L12:L128, "<>-", H12:H128) -> 6.3056461 | E4: =AVERAGE( I12:I37) -> 0.0078413481 | F4: =SUMIF(K12:K128, "<>-", J12:J128) -> 12
B5: =K10 -> LS1 | C5: =AVERAGEIF(K12:K128, "<>-", K12:K128) -> 174.37692 | D5: =AVERAGEIF(L12:L128, "<>-", L12:L128) -> 31.078462 | E5: =AVERAGEIF(K12:K128, "<>-", M12:M128) -> 0.092381094 | F5: =SUMIF(K12:K128, "<>-", N12:N128) -> 5
B6: =O10 -> P1 | C6: =AVERAGEIF(K12:K128, "<>-", O12:O128) -> 156.05385 | D6: =AVERAGEIF(K12:K128, "<>-", P12:P128) -> 6.3893538 | E6: =AVERAGEIF(K12:K128, "<>-", Q12:Q128) -> 0.0072459395 | F6: =SUMIF(K12:K128, "<>-", R12:R128) -> 12
B7: =S10 -> β = 0.08 | C7: =AVERAGEIF(K12:K128, "<>-", S12:S128) -> 154.32308 | D7: =AVERAGEIF(K12:K128, "<>-", T12:T128) -> 4.7454 | E7: =AVERAGEIF(K12:K128, "<>-", U12:U128) -> 0.0076691189 | F7: =SUMIF(K12:K128, "<>-", V12:V128) -> 12
B8: =W10 -> β = 0.18 | C8: =AVERAGEIF(K12:K128, "<>-", W12:W128) -> 155.66154 | D8: =AVERAGEIF(K12:K128, "<>-", X12:X128) -> 7.9938154 | E8: =AVERAGEIF(K12:K128, "<>-", Y12:Y128) -> 0.0057860838 | F8: =SUMIF(K12:K128, "<>-", Z12:Z128) -> 17
C10: Baseline | G10: Gc | K10: LS1 | O10: P1 | S10: β = 0.08 | W10: β = 0.18
B11: Instance | C11: OF | D11: Time | E11: Dev | F11: Best | G11: OF | H11: Time | I11: Dev | J11: Best | K11: OF | L11: Time | M11: Dev | N11: Best | O11: OF | P11: Time | Q11: Dev | R11: Best | S11: OF | T11: Time | U11: Dev | V11: Best | W11: OF | X11: Time | Y11: Dev | Z11: Best | AR11: #best
B12: 662_bus.mtx | C12: =AVERAGE('execs Table 2'!C116,'execs Table 2'!E116,'execs Table 2'!G116,'execs Table 2'!I116,'execs Table 2'!K116) -> 534.2 | D12: =AVERAGE('execs Table 2'!D116,'execs Table 2'!F116,'execs Table 2'!H116,'execs Table 2'!J116,'execs Table 2'!L116) -> 1.783 | E12: =(C12-$AR12)/$AR12 -> 0.0014998125 | F12: =IF(C12=$AR12,1,0) -> 0 | G12: =AVERAGE('execs Table 2'!C144,'execs Table 2'!E144,'execs Table 2'!G144,'execs Table 2'!I144,'execs Table 2'!K144) -> 533.4 | H12: =AVERAGE('execs Table 2'!D144,'execs Table 2'!F144,'execs Table 2'!H144,'execs Table 2'!J144,'execs Table 2'!L144) -> 2.4178 | I12: =(G12-$AR12)/$AR12 -> 0 | J12: =IF(G12=$AR12,1,0) -> 1 | K12: =AVERAGE('execs Table 2'!C32,'execs Table 2'!E32,'execs Table 2'!G32,'execs Table 2'!I32,'execs Table 2'!K32) -> 539 | L12: =AVERAGE('execs Table 2'!D32,'execs Table 2'!F32,'execs Table 2'!H32,'execs Table 2'!J32,'execs Table 2'!L32) -> 11.8904 | M12: =(K12-$AR12)/$AR12 -> 0.010498688 | N12: =IF(K12=$AR12,1,0) -> 0 | O12: =AVERAGE('execs Table 2'!C4,'execs Table 2'!E4,'execs Table 2'!G4,'execs Table 2'!I4,'execs Table 2'!K4) -> 534.8 | P12: =AVERAGE('execs Table 2'!D4,'execs Table 2'!F4,'execs Table 2'!H4,'execs Table 2'!J4,'execs Table 2'!L4) -> 1.5424 | Q12: =(O12-$AR12)/$AR12 -> 0.0026246719 | R12: =IF(O12=$AR12,1,0) -> 0 | S12: =AVERAGE('execs Table 2'!C60,'execs Table 2'!E60,'execs Table 2'!G60,'execs Table 2'!I60,'execs Table 2'!K60) -> 533.4 | T12: =AVERAGE('execs Table 2'!D60,'execs Table 2'!F60,'execs Table 2'!H60,'execs Table 2'!J60,'execs Table 2'!L60) -> 1.0542 | U12: =(S12-$AR12)/$AR12 -> 0 | V12: =IF(S12=$AR12,1,0) -> 1 | W12: =AVERAGE('execs Table 2'!C88,'execs Table 2'!E88,'execs Table 2'!G88,'execs Table 2'!I88,'execs Table 2'!K88) -> 534 | X12: =AVERAGE('execs Table 2'!D88,'execs Table 2'!F88,'execs Table 2'!H88,'execs Table 2'!J88,'execs Table 2'!L88) -> 2.3182 | Y12: =(W12-$AR12)/$AR12 -> 0.0011248594 | Z12: =IF(W12=$AR12,1,0) -> 0 | AR12: =MIN(C12,G12,K12,O12,S12,W12,AA12,AE12,AI12,AM12) -> 533.4
B13: ash331.mtx | C13: =AVERAGE('execs Table 2'!C117,'execs Table 2'!E117,'execs Table 2'!G117,'execs Table 2'!I117,'execs Table 2'!K117) -> 160.2 | D13: =AVERAGE('execs Table 2'!D117,'execs Table 2'!F117,'execs Table 2'!H117,'execs Table 2'!J117,'execs Table 2'!L117) -> 0.3042 | E13: =(C13-$AR13)/$AR13 -> 0.0025031289 | F13: =IF(C13=$AR13,1,0) -> 0 | G13: =AVERAGE('execs Table 2'!C145,'execs Table 2'!E145,'execs Table 2'!G145,'execs Table 2'!I145,'execs Table 2'!K145) -> 161.2 | H13: =AVERAGE('execs Table 2'!D145,'execs Table 2'!F145,'execs Table 2'!H145,'execs Table 2'!J145,'execs Table 2'!L145) -> 0.2536 | I13: =(G13-$AR13)/$AR13 -> 0.0087609512 | J13: =IF(G13=$AR13,1,0) -> 0 | K13: =AVERAGE('execs Table 2'!C33,'execs Table 2'!E33,'execs Table 2'!G33,'execs Table 2'!I33,'execs Table 2'!K33) -> 181 | L13: =AVERAGE('execs Table 2'!D33,'execs Table 2'!F33,'execs Table 2'!H33,'execs Table 2'!J33,'execs Table 2'!L33) -> 1.2312 | M13: =(K13-$AR13)/$AR13 -> 0.13266583 | N13: =IF(K13=$AR13,1,0) -> 0 | O13: =AVERAGE('execs Table 2'!C5,'execs Table 2'!E5,'execs Table 2'!G5,'execs Table 2'!I5,'execs Table 2'!K5) -> 160.4 | P13: =AVERAGE('execs Table 2'!D5,'execs Table 2'!F5,'execs Table 2'!H5,'execs Table 2'!J5,'execs Table 2'!L5) -> 0.289 | Q13: =(O13-$AR13)/$AR13 -> 0.0037546934 | R13: =IF(O13=$AR13,1,0) -> 0 | S13: =AVERAGE('execs Table 2'!C61,'execs Table 2'!E61,'execs Table 2'!G61,'execs Table 2'!I61,'execs Table 2'!K61) -> 160.4 | T13: =AVERAGE('execs Table 2'!D61,'execs Table 2'!F61,'execs Table 2'!H61,'execs Table 2'!J61,'execs Table 2'!L61) -> 0.2518 | U13: =(S13-$AR13)/$AR13 -> 0.0037546934 | V13: =IF(S13=$AR13,1,0) -> 0 | W13: =AVERAGE('execs Table 2'!C89,'execs Table 2'!E89,'execs Table 2'!G89,'execs Table 2'!I89,'execs Table 2'!K89) -> 159.8 | X13: =AVERAGE('execs Table 2'!D89,'execs Table 2'!F89,'execs Table 2'!H89,'execs Table 2'!J89,'execs Table 2'!L89) -> 0.368 | Y13: =(W13-$AR13)/$AR13 -> 0 | Z13: =IF(W13=$AR13,1,0) -> 1 | AR13: =MIN(C13,G13,K13,O13,S13,W13,AA13,AE13,AI13,AM13) -> 159.8
B14: bcspwr04.mtx | C14: =AVERAGE('execs Table 2'!C118,'execs Table 2'!E118,'execs Table 2'!G118,'execs Table 2'!I118,'execs Table 2'!K118) -> 180.2 | D14: =AVERAGE('execs Table 2'!D118,'execs Table 2'!F118,'execs Table 2'!H118,'execs Table 2'!J118,'execs Table 2'!L118) -> 0.5716 | E14: =(C14-$AR14)/$AR14 -> 0 | F14: =IF(C14=$AR14,1,0) -> 1 | G14: =AVERAGE('execs Table 2'!C146,'execs Table 2'!E146,'execs Table 2'!G146,'execs Table 2'!I146,'execs Table 2'!K146) -> 180.6 | H14: =AVERAGE('execs Table 2'!D146,'execs Table 2'!F146,'execs Table 2'!H146,'execs Table 2'!J146,'execs Table 2'!L146) -> 0.6534 | I14: =(G14-$AR14)/$AR14 -> 0.0022197558 | J14: =IF(G14=$AR14,1,0) -> 0 | K14: =AVERAGE('execs Table 2'!C34,'execs Table 2'!E34,'execs Table 2'!G34,'execs Table 2'!I34,'execs Table 2'!K34) -> 185 | L14: =AVERAGE('execs Table 2'!D34,'execs Table 2'!F34,'execs Table 2'!H34,'execs Table 2'!J34,'execs Table 2'!L34) -> 1.8182 | M14: =(K14-$AR14)/$AR14 -> 0.02663707 | N14: =IF(K14=$AR14,1,0) -> 0 | O14: =AVERAGE('execs Table 2'!C6,'execs Table 2'!E6,'execs Table 2'!G6,'execs Table 2'!I6,'execs Table 2'!K6) -> 180.8 | P14: =AVERAGE('execs Table 2'!D6,'execs Table 2'!F6,'execs Table 2'!H6,'execs Table 2'!J6,'execs Table 2'!L6) -> 0.49 | Q14: =(O14-$AR14)/$AR14 -> 0.0033296337 | R14: =IF(O14=$AR14,1,0) -> 0 | S14: =AVERAGE('execs Table 2'!C62,'execs Table 2'!E62,'execs Table 2'!G62,'execs Table 2'!I62,'execs Table 2'!K62) -> 180.6 | T14: =AVERAGE('execs Table 2'!D62,'execs Table 2'!F62,'execs Table 2'!H62,'execs Table 2'!J62,'execs Table 2'!L62) -> 0.3976 | U14: =(S14-$AR14)/$AR14 -> 0.0022197558 | V14: =IF(S14=$AR14,1,0) -> 0 | W14: =AVERAGE('execs Table 2'!C90,'execs Table 2'!E90,'execs Table 2'!G90,'execs Table 2'!I90,'execs Table 2'!K90) -> 180.6 | X14: =AVERAGE('execs Table 2'!D90,'execs Table 2'!F90,'execs Table 2'!H90,'execs Table 2'!J90,'execs Table 2'!L90) -> 0.838 | Y14: =(W14-$AR14)/$AR14 -> 0.0022197558 | Z14: =IF(W14=$AR14,1,0) -> 0 | AR14: =MIN(C14,G14,K14,O14,S14,W14,AA14,AE14,AI14,AM14) -> 180.2
B15: bcsstk01.mtx | C15: =AVERAGE('execs Table 2'!C119,'execs Table 2'!E119,'execs Table 2'!G119,'execs Table 2'!I119,'execs Table 2'!K119) -> 18 | D15: =AVERAGE('execs Table 2'!D119,'execs Table 2'!F119,'execs Table 2'!H119,'execs Table 2'!J119,'execs Table 2'!L119) -> 0.0216 | E15: =(C15-$AR15)/$AR15 -> 0 | F15: =IF(C15=$AR15,1,0) -> 1 | G15: =AVERAGE('execs Table 2'!C147,'execs Table 2'!E147,'execs Table 2'!G147,'execs Table 2'!I147,'execs Table 2'!K147) -> 18.6 | H15: =AVERAGE('execs Table 2'!D147,'execs Table 2'!F147,'execs Table 2'!H147,'execs Table 2'!J147,'execs Table 2'!L147) -> 0.0188 | I15: =(G15-$AR15)/$AR15 -> 0.033333333 | J15: =IF(G15=$AR15,1,0) -> 0 | K15: =AVERAGE('execs Table 2'!C35,'execs Table 2'!E35,'execs Table 2'!G35,'execs Table 2'!I35,'execs Table 2'!K35) -> 22 | L15: =AVERAGE('execs Table 2'!D35,'execs Table 2'!F35,'execs Table 2'!H35,'execs Table 2'!J35,'execs Table 2'!L35) -> 0.0364 | M15: =(K15-$AR15)/$AR15 -> 0.22222222 | N15: =IF(K15=$AR15,1,0) -> 0 | O15: =AVERAGE('execs Table 2'!C7,'execs Table 2'!E7,'execs Table 2'!G7,'execs Table 2'!I7,'execs Table 2'!K7) -> 18 | P15: =AVERAGE('execs Table 2'!D7,'execs Table 2'!F7,'execs Table 2'!H7,'execs Table 2'!J7,'execs Table 2'!L7) -> 0.0186 | Q15: =(O15-$AR15)/$AR15 -> 0 | R15: =IF(O15=$AR15,1,0) -> 1 | S15: =AVERAGE('execs Table 2'!C63,'execs Table 2'!E63,'execs Table 2'!G63,'execs Table 2'!I63,'execs Table 2'!K63) -> 18 | T15: =AVERAGE('execs Table 2'!D63,'execs Table 2'!F63,'execs Table 2'!H63,'execs Table 2'!J63,'execs Table 2'!L63) -> 0.0158 | U15: =(S15-$AR15)/$AR15 -> 0 | V15: =IF(S15=$AR15,1,0) -> 1 | W15: =AVERAGE('execs Table 2'!C91,'execs Table 2'!E91,'execs Table 2'!G91,'execs Table 2'!I91,'execs Table 2'!K91) -> 18 | X15: =AVERAGE('execs Table 2'!D91,'execs Table 2'!F91,'execs Table 2'!H91,'execs Table 2'!J91,'execs Table 2'!L91) -> 0.0208 | Y15: =(W15-$AR15)/$AR15 -> 0 | Z15: =IF(W15=$AR15,1,0) -> 1 | AR15: =MIN(C15,G15,K15,O15,S15,W15,AA15,AE15,AI15,AM15) -> 18
B16: bp_0.mtx | C16: =AVERAGE('execs Table 2'!C120,'execs Table 2'!E120,'execs Table 2'!G120,'execs Table 2'!I120,'execs Table 2'!K120) -> 333 | D16: =AVERAGE('execs Table 2'!D120,'execs Table 2'!F120,'execs Table 2'!H120,'execs Table 2'!J120,'execs Table 2'!L120) -> 19.2766 | E16: =(C16-$AR16)/$AR16 -> 0 | F16: =IF(C16=$AR16,1,0) -> 1 | G16: =AVERAGE('execs Table 2'!C148,'execs Table 2'!E148,'execs Table 2'!G148,'execs Table 2'!I148,'execs Table 2'!K148) -> 335.4 | H16: =AVERAGE('execs Table 2'!D148,'execs Table 2'!F148,'execs Table 2'!H148,'execs Table 2'!J148,'execs Table 2'!L148) -> 17.6284 | I16: =(G16-$AR16)/$AR16 -> 0.0072072072 | J16: =IF(G16=$AR16,1,0) -> 0 | K16: =AVERAGE('execs Table 2'!C36,'execs Table 2'!E36,'execs Table 2'!G36,'execs Table 2'!I36,'execs Table 2'!K36) -> 347.2 | L16: =AVERAGE('execs Table 2'!D36,'execs Table 2'!F36,'execs Table 2'!H36,'execs Table 2'!J36,'execs Table 2'!L36) -> 132.9384 | M16: =(K16-$AR16)/$AR16 -> 0.042642643 | N16: =IF(K16=$AR16,1,0) -> 0 | O16: =AVERAGE('execs Table 2'!C8,'execs Table 2'!E8,'execs Table 2'!G8,'execs Table 2'!I8,'execs Table 2'!K8) -> 333.8 | P16: =AVERAGE('execs Table 2'!D8,'execs Table 2'!F8,'execs Table 2'!H8,'execs Table 2'!J8,'execs Table 2'!L8) -> 18.763 | Q16: =(O16-$AR16)/$AR16 -> 0.0024024024 | R16: =IF(O16=$AR16,1,0) -> 0 | S16: =AVERAGE('execs Table 2'!C64,'execs Table 2'!E64,'execs Table 2'!G64,'execs Table 2'!I64,'execs Table 2'!K64) -> 333.4 | T16: =AVERAGE('execs Table 2'!D64,'execs Table 2'!F64,'execs Table 2'!H64,'execs Table 2'!J64,'execs Table 2'!L64) -> 15.4398 | U16: =(S16-$AR16)/$AR16 -> 0.0012012012 | V16: =IF(S16=$AR16,1,0) -> 0 | W16: =AVERAGE('execs Table 2'!C92,'execs Table 2'!E92,'execs Table 2'!G92,'execs Table 2'!I92,'execs Table 2'!K92) -> 333.4 | X16: =AVERAGE('execs Table 2'!D92,'execs Table 2'!F92,'execs Table 2'!H92,'execs Table 2'!J92,'execs Table 2'!L92) -> 23.1158 | Y16: =(W16-$AR16)/$AR16 -> 0.0012012012 | Z16: =IF(W16=$AR16,1,0) -> 0 | AR16: =MIN(C16,G16,K16,O16,S16,W16,AA16,AE16,AI16,AM16) -> 333
B17: can_161.mtx | C17: =AVERAGE('execs Table 2'!C121,'execs Table 2'!E121,'execs Table 2'!G121,'execs Table 2'!I121,'execs Table 2'!K121) -> 57 | D17: =AVERAGE('execs Table 2'!D121,'execs Table 2'!F121,'execs Table 2'!H121,'execs Table 2'!J121,'execs Table 2'!L121) -> 0.0862 | E17: =(C17-$AR17)/$AR17 -> 0 | F17: =IF(C17=$AR17,1,0) -> 1 | G17: =AVERAGE('execs Table 2'!C149,'execs Table 2'!E149,'execs Table 2'!G149,'execs Table 2'!I149,'execs Table 2'!K149) -> 57 | H17: =AVERAGE('execs Table 2'!D149,'execs Table 2'!F149,'execs Table 2'!H149,'execs Table 2'!J149,'execs Table 2'!L149) -> 0.088800001 | I17: =(G17-$AR17)/$AR17 -> 0 | J17: =IF(G17=$AR17,1,0) -> 1 | K17: =AVERAGE('execs Table 2'!C37,'execs Table 2'!E37,'execs Table 2'!G37,'execs Table 2'!I37,'execs Table 2'!K37) -> 57.4 | L17: =AVERAGE('execs Table 2'!D37,'execs Table 2'!F37,'execs Table 2'!H37,'execs Table 2'!J37,'execs Table 2'!L37) -> 0.7224 | M17: =(K17-$AR17)/$AR17 -> 0.0070175439 | N17: =IF(K17=$AR17,1,0) -> 0 | O17: =AVERAGE('execs Table 2'!C9,'execs Table 2'!E9,'execs Table 2'!G9,'execs Table 2'!I9,'execs Table 2'!K9) -> 57 | P17: =AVERAGE('execs Table 2'!D9,'execs Table 2'!F9,'execs Table 2'!H9,'execs Table 2'!J9,'execs Table 2'!L9) -> 0.086400001 | Q17: =(O17-$AR17)/$AR17 -> 0 | R17: =IF(O17=$AR17,1,0) -> 1 | S17: =AVERAGE('execs Table 2'!C65,'execs Table 2'!E65,'execs Table 2'!G65,'execs Table 2'!I65,'execs Table 2'!K65) -> 57 | T17: =AVERAGE('execs Table 2'!D65,'execs Table 2'!F65,'execs Table 2'!H65,'execs Table 2'!J65,'execs Table 2'!L65) -> 0.0836 | U17: =(S17-$AR17)/$AR17 -> 0 | V17: =IF(S17=$AR17,1,0) -> 1 | W17: =AVERAGE('execs Table 2'!C93,'execs Table 2'!E93,'execs Table 2'!G93,'execs Table 2'!I93,'execs Table 2'!K93) -> 57 | X17: =AVERAGE('execs Table 2'!D93,'execs Table 2'!F93,'execs Table 2'!H93,'execs Table 2'!J93,'execs Table 2'!L93) -> 0.093200001 | Y17: =(W17-$AR17)/$AR17 -> 0 | Z17: =IF(W17=$AR17,1,0) -> 1 | AR17: =MIN(C17,G17,K17,O17,S17,W17,AA17,AE17,AI17,AM17) -> 57
B18: cavity03.mtx | C18: =AVERAGE('execs Table 2'!C122,'execs Table 2'!E122,'execs Table 2'!G122,'execs Table 2'!I122,'execs Table 2'!K122) -> 26 | D18: =AVERAGE('execs Table 2'!D122,'execs Table 2'!F122,'execs Table 2'!H122,'execs Table 2'!J122,'execs Table 2'!L122) -> 6.4646 | E18: =(C18-$AR18)/$AR18 -> 0 | F18: =IF(C18=$AR18,1,0) -> 1 | G18: =AVERAGE('execs Table 2'!C150,'execs Table 2'!E150,'execs Table 2'!G150,'execs Table 2'!I150,'execs Table 2'!K150) -> 26 | H18: =AVERAGE('execs Table 2'!D150,'execs Table 2'!F150,'execs Table 2'!H150,'execs Table 2'!J150,'execs Table 2'!L150) -> 6.4794001 | I18: =(G18-$AR18)/$AR18 -> 0 | J18: =IF(G18=$AR18,1,0) -> 1 | K18: =AVERAGE('execs Table 2'!C38,'execs Table 2'!E38,'execs Table 2'!G38,'execs Table 2'!I38,'execs Table 2'!K38) -> 26 | L18: =AVERAGE('execs Table 2'!D38,'execs Table 2'!F38,'execs Table 2'!H38,'execs Table 2'!J38,'execs Table 2'!L38) -> 22.7672 | M18: =(K18-$AR18)/$AR18 -> 0 | N18: =IF(K18=$AR18,1,0) -> 1 | O18: =AVERAGE('execs Table 2'!C10,'execs Table 2'!E10,'execs Table 2'!G10,'execs Table 2'!I10,'execs Table 2'!K10) -> 26 | P18: =AVERAGE('execs Table 2'!D10,'execs Table 2'!F10,'execs Table 2'!H10,'execs Table 2'!J10,'execs Table 2'!L10) -> 6.0879998 | Q18: =(O18-$AR18)/$AR18 -> 0 | R18: =IF(O18=$AR18,1,0) -> 1 | S18: =AVERAGE('execs Table 2'!C66,'execs Table 2'!E66,'execs Table 2'!G66,'execs Table 2'!I66,'execs Table 2'!K66) -> 26 | T18: =AVERAGE('execs Table 2'!D66,'execs Table 2'!F66,'execs Table 2'!H66,'execs Table 2'!J66,'execs Table 2'!L66) -> 5.683 | U18: =(S18-$AR18)/$AR18 -> 0 | V18: =IF(S18=$AR18,1,0) -> 1 | W18: =AVERAGE('execs Table 2'!C94,'execs Table 2'!E94,'execs Table 2'!G94,'execs Table 2'!I94,'execs Table 2'!K94) -> 26 | X18: =AVERAGE('execs Table 2'!D94,'execs Table 2'!F94,'execs Table 2'!H94,'execs Table 2'!J94,'execs Table 2'!L94) -> 6.9178 | Y18: =(W18-$AR18)/$AR18 -> 0 | Z18: =IF(W18=$AR18,1,0) -> 1 | AR18: =MIN(C18,G18,K18,O18,S18,W18,AA18,AE18,AI18,AM18) -> 26
B19: ck656.mtx | C19: =AVERAGE('execs Table 2'!C123,'execs Table 2'!E123,'execs Table 2'!G123,'execs Table 2'!I123,'execs Table 2'!K123) -> 295 | D19: =AVERAGE('execs Table 2'!D123,'execs Table 2'!F123,'execs Table 2'!H123,'execs Table 2'!J123,'execs Table 2'!L123) -> 33.276599 | E19: =(C19-$AR19)/$AR19 -> 0.0068259386 | F19: =IF(C19=$AR19,1,0) -> 0 | G19: =AVERAGE('execs Table 2'!C151,'execs Table 2'!E151,'execs Table 2'!G151,'execs Table 2'!I151,'execs Table 2'!K151) -> 298.4 | H19: =AVERAGE('execs Table 2'!D151,'execs Table 2'!F151,'execs Table 2'!H151,'execs Table 2'!J151,'execs Table 2'!L151) -> 29.4406 | I19: =(G19-$AR19)/$AR19 -> 0.018430034 | J19: =IF(G19=$AR19,1,0) -> 0 | K19: =AVERAGE('execs Table 2'!C39,'execs Table 2'!E39,'execs Table 2'!G39,'execs Table 2'!I39,'execs Table 2'!K39) -> 302 | L19: =AVERAGE('execs Table 2'!D39,'execs Table 2'!F39,'execs Table 2'!H39,'execs Table 2'!J39,'execs Table 2'!L39) -> 66.821999 | M19: =(K19-$AR19)/$AR19 -> 0.030716724 | N19: =IF(K19=$AR19,1,0) -> 0 | O19: =AVERAGE('execs Table 2'!C11,'execs Table 2'!E11,'execs Table 2'!G11,'execs Table 2'!I11,'execs Table 2'!K11) -> 293 | P19: =AVERAGE('execs Table 2'!D11,'execs Table 2'!F11,'execs Table 2'!H11,'execs Table 2'!J11,'execs Table 2'!L11) -> 40.9072 | Q19: =(O19-$AR19)/$AR19 -> 0 | R19: =IF(O19=$AR19,1,0) -> 1 | S19: =AVERAGE('execs Table 2'!C67,'execs Table 2'!E67,'execs Table 2'!G67,'execs Table 2'!I67,'execs Table 2'!K67) -> 294.8 | T19: =AVERAGE('execs Table 2'!D67,'execs Table 2'!F67,'execs Table 2'!H67,'execs Table 2'!J67,'execs Table 2'!L67) -> 26.4606 | U19: =(S19-$AR19)/$AR19 -> 0.0061433447 | V19: =IF(S19=$AR19,1,0) -> 0 | W19: =AVERAGE('execs Table 2'!C95,'execs Table 2'!E95,'execs Table 2'!G95,'execs Table 2'!I95,'execs Table 2'!K95) -> 297.6 | X19: =AVERAGE('execs Table 2'!D95,'execs Table 2'!F95,'execs Table 2'!H95,'execs Table 2'!J95,'execs Table 2'!L95) -> 45.446201 | Y19: =(W19-$AR19)/$AR19 -> 0.015699659 | Z19: =IF(W19=$AR19,1,0) -> 0 | AR19: =MIN(C19,G19,K19,O19,S19,W19,AA19,AE19,AI19,AM19) -> 293
B20: dwt_361.mtx | C20: =AVERAGE('execs Table 2'!C124,'execs Table 2'!E124,'execs Table 2'!G124,'execs Table 2'!I124,'execs Table 2'!K124) -> 150 | D20: =AVERAGE('execs Table 2'!D124,'execs Table 2'!F124,'execs Table 2'!H124,'execs Table 2'!J124,'execs Table 2'!L124) -> 0.73779999 | E20: =(C20-$AR20)/$AR20 -> 0.0026737968 | F20: =IF(C20=$AR20,1,0) -> 0 | G20: =AVERAGE('execs Table 2'!C152,'execs Table 2'!E152,'execs Table 2'!G152,'execs Table 2'!I152,'execs Table 2'!K152) -> 150.2 | H20: =AVERAGE('execs Table 2'!D152,'execs Table 2'!F152,'execs Table 2'!H152,'execs Table 2'!J152,'execs Table 2'!L152) -> 0.7752 | I20: =(G20-$AR20)/$AR20 -> 0.0040106952 | J20: =IF(G20=$AR20,1,0) -> 0 | K20: =AVERAGE('execs Table 2'!C40,'execs Table 2'!E40,'execs Table 2'!G40,'execs Table 2'!I40,'execs Table 2'!K40) -> 156.4 | L20: =AVERAGE('execs Table 2'!D40,'execs Table 2'!F40,'execs Table 2'!H40,'execs Table 2'!J40,'execs Table 2'!L40) -> 5.7332 | M20: =(K20-$AR20)/$AR20 -> 0.045454545 | N20: =IF(K20=$AR20,1,0) -> 0 | O20: =AVERAGE('execs Table 2'!C12,'execs Table 2'!E12,'execs Table 2'!G12,'execs Table 2'!I12,'execs Table 2'!K12) -> 150.6 | P20: =AVERAGE('execs Table 2'!D12,'execs Table 2'!F12,'execs Table 2'!H12,'execs Table 2'!J12,'execs Table 2'!L12) -> 0.79940001 | Q20: =(O20-$AR20)/$AR20 -> 0.006684492 | R20: =IF(O20=$AR20,1,0) -> 0 | S20: =AVERAGE('execs Table 2'!C68,'execs Table 2'!E68,'execs Table 2'!G68,'execs Table 2'!I68,'execs Table 2'!K68) -> 149.6 | T20: =AVERAGE('execs Table 2'!D68,'execs Table 2'!F68,'execs Table 2'!H68,'execs Table 2'!J68,'execs Table 2'!L68) -> 0.67360001 | U20: =(S20-$AR20)/$AR20 -> 0 | V20: =IF(S20=$AR20,1,0) -> 1 | W20: =AVERAGE('execs Table 2'!C96,'execs Table 2'!E96,'execs Table 2'!G96,'execs Table 2'!I96,'execs Table 2'!K96) -> 150.2 | X20: =AVERAGE('execs Table 2'!D96,'execs Table 2'!F96,'execs Table 2'!H96,'execs Table 2'!J96,'execs Table 2'!L96) -> 0.91839999 | Y20: =(W20-$AR20)/$AR20 -> 0.0040106952 | Z20: =IF(W20=$AR20,1,0) -> 0 | AR20: =MIN(C20,G20,K20,O20,S20,W20,AA20,AE20,AI20,AM20) -> 149.6
B21: dwt_59.mtx | C21: =AVERAGE('execs Table 2'!C125,'execs Table 2'!E125,'execs Table 2'!G125,'execs Table 2'!I125,'execs Table 2'!K125) -> 43.6 | D21: =AVERAGE('execs Table 2'!D125,'execs Table 2'!F125,'execs Table 2'!H125,'execs Table 2'!J125,'execs Table 2'!L125) -> 0.0072000002 | E21: =(C21-$AR21)/$AR21 -> 0 | F21: =IF(C21=$AR21,1,0) -> 1 | G21: =AVERAGE('execs Table 2'!C153,'execs Table 2'!E153,'execs Table 2'!G153,'execs Table 2'!I153,'execs Table 2'!K153) -> 43.6 | H21: =AVERAGE('execs Table 2'!D153,'execs Table 2'!F153,'execs Table 2'!H153,'execs Table 2'!J153,'execs Table 2'!L153) -> 0.0074000001 | I21: =(G21-$AR21)/$AR21 -> 0 | J21: =IF(G21=$AR21,1,0) -> 1 | K21: =AVERAGE('execs Table 2'!C41,'execs Table 2'!E41,'execs Table 2'!G41,'execs Table 2'!I41,'execs Table 2'!K41) -> 44.6 | L21: =AVERAGE('execs Table 2'!D41,'execs Table 2'!F41,'execs Table 2'!H41,'execs Table 2'!J41,'execs Table 2'!L41) -> 0.0202 | M21: =(K21-$AR21)/$AR21 -> 0.02293578 | N21: =IF(K21=$AR21,1,0) -> 0 | O21: =AVERAGE('execs Table 2'!C13,'execs Table 2'!E13,'execs Table 2'!G13,'execs Table 2'!I13,'execs Table 2'!K13) -> 43.8 | P21: =AVERAGE('execs Table 2'!D13,'execs Table 2'!F13,'execs Table 2'!H13,'execs Table 2'!J13,'execs Table 2'!L13) -> 0.0076000001 | Q21: =(O21-$AR21)/$AR21 -> 0.004587156 | R21: =IF(O21=$AR21,1,0) -> 0 | S21: =AVERAGE('execs Table 2'!C69,'execs Table 2'!E69,'execs Table 2'!G69,'execs Table 2'!I69,'execs Table 2'!K69) -> 44 | T21: =AVERAGE('execs Table 2'!D69,'execs Table 2'!F69,'execs Table 2'!H69,'execs Table 2'!J69,'execs Table 2'!L69) -> 0.0050000001 | U21: =(S21-$AR21)/$AR21 -> 0.0091743119 | V21: =IF(S21=$AR21,1,0) -> 0 | W21: =AVERAGE('execs Table 2'!C97,'execs Table 2'!E97,'execs Table 2'!G97,'execs Table 2'!I97,'execs Table 2'!K97) -> 43.6 | X21: =AVERAGE('execs Table 2'!D97,'execs Table 2'!F97,'execs Table 2'!H97,'execs Table 2'!J97,'execs Table 2'!L97) -> 0.0086000001 | Y21: =(W21-$AR21)/$AR21 -> 0 | Z21: =IF(W21=$AR21,1,0) -> 1 | AR21: =MIN(C21,G21,K21,O21,S21,W21,AA21,AE21,AI21,AM21) -> 43.6
B22: e05r0200.mtx | C22: =AVERAGE('execs Table 2'!C126,'execs Table 2'!E126,'execs Table 2'!G126,'execs Table 2'!I126,'execs Table 2'!K126) -> 18 | D22: =AVERAGE('execs Table 2'!D126,'execs Table 2'!F126,'execs Table 2'!H126,'execs Table 2'!J126,'execs Table 2'!L126) -> 11.9918 | E22: =(C22-$AR22)/$AR22 -> 0 | F22: =IF(C22=$AR22,1,0) -> 1 | G22: =AVERAGE('execs Table 2'!C154,'execs Table 2'!E154,'execs Table 2'!G154,'execs Table 2'!I154,'execs Table 2'!K154) -> 18 | H22: =AVERAGE('execs Table 2'!D154,'execs Table 2'!F154,'execs Table 2'!H154,'execs Table 2'!J154,'execs Table 2'!L154) -> 11.7066 | I22: =(G22-$AR22)/$AR22 -> 0 | J22: =IF(G22=$AR22,1,0) -> 1 | K22: =AVERAGE('execs Table 2'!C42,'execs Table 2'!E42,'execs Table 2'!G42,'execs Table 2'!I42,'execs Table 2'!K42) -> 18 | L22: =AVERAGE('execs Table 2'!D42,'execs Table 2'!F42,'execs Table 2'!H42,'execs Table 2'!J42,'execs Table 2'!L42) -> 40.876 | M22: =(K22-$AR22)/$AR22 -> 0 | N22: =IF(K22=$AR22,1,0) -> 1 | O22: =AVERAGE('execs Table 2'!C14,'execs Table 2'!E14,'execs Table 2'!G14,'execs Table 2'!I14,'execs Table 2'!K14) -> 18 | P22: =AVERAGE('execs Table 2'!D14,'execs Table 2'!F14,'execs Table 2'!H14,'execs Table 2'!J14,'execs Table 2'!L14) -> 11.1266 | Q22: =(O22-$AR22)/$AR22 -> 0 | R22: =IF(O22=$AR22,1,0) -> 1 | S22: =AVERAGE('execs Table 2'!C70,'execs Table 2'!E70,'execs Table 2'!G70,'execs Table 2'!I70,'execs Table 2'!K70) -> 18 | T22: =AVERAGE('execs Table 2'!D70,'execs Table 2'!F70,'execs Table 2'!H70,'execs Table 2'!J70,'execs Table 2'!L70) -> 10.1384 | U22: =(S22-$AR22)/$AR22 -> 0 | V22: =IF(S22=$AR22,1,0) -> 1 | W22: =AVERAGE('execs Table 2'!C98,'execs Table 2'!E98,'execs Table 2'!G98,'execs Table 2'!I98,'execs Table 2'!K98) -> 18 | X22: =AVERAGE('execs Table 2'!D98,'execs Table 2'!F98,'execs Table 2'!H98,'execs Table 2'!J98,'execs Table 2'!L98) -> 13.014 | Y22: =(W22-$AR22)/$AR22 -> 0 | Z22: =IF(W22=$AR22,1,0) -> 1 | AR22: =MIN(C22,G22,K22,O22,S22,W22,AA22,AE22,AI22,AM22) -> 18
B23: fs_541_2.mtx | C23: =AVERAGE('execs Table 2'!C127,'execs Table 2'!E127,'execs Table 2'!G127,'execs Table 2'!I127,'execs Table 2'!K127) -> 3 | D23: =AVERAGE('execs Table 2'!D127,'execs Table 2'!F127,'execs Table 2'!H127,'execs Table 2'!J127,'execs Table 2'!L127) -> 15.6832 | E23: =(C23-$AR23)/$AR23 -> 0 | F23: =IF(C23=$AR23,1,0) -> 1 | G23: =AVERAGE('execs Table 2'!C155,'execs Table 2'!E155,'execs Table 2'!G155,'execs Table 2'!I155,'execs Table 2'!K155) -> 3 | H23: =AVERAGE('execs Table 2'!D155,'execs Table 2'!F155,'execs Table 2'!H155,'execs Table 2'!J155,'execs Table 2'!L155) -> 16.7866 | I23: =(G23-$AR23)/$AR23 -> 0 | J23: =IF(G23=$AR23,1,0) -> 1 | K23: =AVERAGE('execs Table 2'!C43,'execs Table 2'!E43,'execs Table 2'!G43,'execs Table 2'!I43,'execs Table 2'!K43) -> 3 | L23: =AVERAGE('execs Table 2'!D43,'execs Table 2'!F43,'execs Table 2'!H43,'execs Table 2'!J43,'execs Table 2'!L43) -> 96.309399 | M23: =(K23-$AR23)/$AR23 -> 0 | N23: =IF(K23=$AR23,1,0) -> 1 | O23: =AVERAGE('execs Table 2'!C15,'execs Table 2'!E15,'execs Table 2'!G15,'execs Table 2'!I15,'execs Table 2'!K15) -> 3 | P23: =AVERAGE('execs Table 2'!D15,'execs Table 2'!F15,'execs Table 2'!H15,'execs Table 2'!J15,'execs Table 2'!L15) -> 12.496 | Q23: =(O23-$AR23)/$AR23 -> 0 | R23: =IF(O23=$AR23,1,0) -> 1 | S23: =AVERAGE('execs Table 2'!C71,'execs Table 2'!E71,'execs Table 2'!G71,'execs Table 2'!I71,'execs Table 2'!K71) -> 3 | T23: =AVERAGE('execs Table 2'!D71,'execs Table 2'!F71,'execs Table 2'!H71,'execs Table 2'!J71,'execs Table 2'!L71) -> 11.3722 | U23: =(S23-$AR23)/$AR23 -> 0 | V23: =IF(S23=$AR23,1,0) -> 1 | W23: =AVERAGE('execs Table 2'!C99,'execs Table 2'!E99,'execs Table 2'!G99,'execs Table 2'!I99,'execs Table 2'!K99) -> 3 | X23: =AVERAGE('execs Table 2'!D99,'execs Table 2'!F99,'execs Table 2'!H99,'execs Table 2'!J99,'execs Table 2'!L99) -> 20.2556 | Y23: =(W23-$AR23)/$AR23 -> 0 | Z23: =IF(W23=$AR23,1,0) -> 1 | AR23: =MIN(C23,G23,K23,O23,S23,W23,AA23,AE23,AI23,AM23) -> 3
... B37: will199.mtx | C37: =AVERAGE('execs Table 2'!C141,'execs Table 2'!E141,'execs Table 2'!G141,'execs Table 2'!I141,'execs Table 2'!K141) -> 93.4 | D37: =AVERAGE('execs Table 2'!D141,'execs Table 2'!F141,'execs Table 2'!H141,'execs Table 2'!J141,'execs Table 2'!L141) -> 0.3208 | E37: =(C37-$AR37)/$AR37 -> 0.0086393089 | F37: =IF(C37=$AR37,1,0) -> 0 | G37: =AVERAGE('execs Table 2'!C169,'execs Table 2'!E169,'execs Table 2'!G169,'execs Table 2'!I169,'execs Table 2'!K169) -> 94.6 | H37: =AVERAGE('execs Table 2'!D169,'execs Table 2'!F169,'execs Table 2'!H169,'execs Table 2'!J169,'execs Table 2'!L169) -> 0.2812 | I37: =(G37-$AR37)/$AR37 -> 0.021598272 | J37: =IF(G37=$AR37,1,0) -> 0 | K37: =AVERAGE('execs Table 2'!C57,'execs Table 2'!E57,'execs Table 2'!G57,'execs Table 2'!I57,'execs Table 2'!K57) -> 99.8 | L37: =AVERAGE('execs Table 2'!D57,'execs Table 2'!F57,'execs Table 2'!H57,'execs Table 2'!J57,'execs Table 2'!L57) -> 1.3362 | M37: =(K37-$AR37)/$AR37 -> 0.07775378 | N37: =IF(K37=$AR37,1,0) -> 0 | O37: =AVERAGE('execs Table 2'!C29,'execs Table 2'!E29,'execs Table 2'!G29,'execs Table 2'!I29,'execs Table 2'!K29) -> 92.8 | P37: =AVERAGE('execs Table 2'!D29,'execs Table 2'!F29,'execs Table 2'!H29,'execs Table 2'!J29,'execs Table 2'!L29) -> 0.3038 | Q37: =(O37-$AR37)/$AR37 -> 0.0021598272 | R37: =IF(O37=$AR37,1,0) -> 0 | S37: =AVERAGE('execs Table 2'!C85,'execs Table 2'!E85,'execs Table 2'!G85,'execs Table 2'!I85,'execs Table 2'!K85) -> 94 | T37: =AVERAGE('execs Table 2'!D85,'execs Table 2'!F85,'execs Table 2'!H85,'execs Table 2'!J85,'execs Table 2'!L85) -> 0.2762 | U37: =(S37-$AR37)/$AR37 -> 0.01511879 | V37: =IF(S37=$AR37,1,0) -> 0 | W37: =AVERAGE('execs Table 2'!C113,'execs Table 2'!E113,'execs Table 2'!G113,'execs Table 2'!I113,'execs Table 2'!K113) -> 92.6 | X37: =AVERAGE('execs Table 2'!D113,'execs Table 2'!F113,'execs Table 2'!H113,'execs Table 2'!J113,'execs Table 2'!L113) -> 0.3022 | Y37: =(W37-$AR37)/$AR37 -> 0 | Z37: =IF(W37=$AR37,1,0) -> 1 | AR37: =MIN(C37,G37,K37,O37,S37,W37,AA37,AE37,AI37,AM37) -> 92.6

Sheet Table 3
B2: Post-processing? | C2: Avg. | D2: Time | E2: Dev. | F2: #best
B3: =C6 -> No | C3: =AVERAGE(C8:C33) -> 160.07692 | D3: =AVERAGE(D8:D33) -> 6.4622308 | E3: =AVERAGE(E8:E33) -> 0.020703629 | F3: =SUM(F8:F33) -> 12
B4: =G6 -> Yes | C4: =AVERAGE(G8:G33) -> 154.30769 | D4: =AVERAGE(H8:H33) -> 5.6006923 | E4: =AVERAGE(I8:I33) -> 0 | F4: =SUM(J8:J33) -> 26
C6: No | G6: Yes
B7: Instance | C7: OF | D7: Time | E7: Dev | F7: Best | G7: OF | H7: Time | I7: Dev | J7: Best | O7: #best
B8: 662_bus.mtx | C8: 545 | D8: 0.92500001 | E8: =(C8-$O8)/$O8 -> 0.02443609 | F8: =IF(C8=$O8,1,0) -> 0 | G8: 532 | H8: 1.704 | I8: =(G8-$O8)/$O8 -> 0 | J8: =IF(G8=$O8,1,0) -> 1 | O8: =MIN(C8,G8) -> 532
B9: ash331.mtx | C9: 164 | D9: 0.51499999 | E9: =(C9-$O9)/$O9 -> 0.01863354 | F9: =IF(C9=$O9,1,0) -> 0 | G9: 161 | H9: 0.16500001 | I9: =(G9-$O9)/$O9 -> 0 | J9: =IF(G9=$O9,1,0) -> 1 | O9: =MIN(C9,G9) -> 161
B10: bcspwr04.mtx | C10: 184 | D10: 0.287 | E10: =(C10-$O10)/$O10 -> 0.022222222 | F10: =IF(C10=$O10,1,0) -> 0 | G10: 180 | H10: 0.35600001 | I10: =(G10-$O10)/$O10 -> 0 | J10: =IF(G10=$O10,1,0) -> 1 | O10: =MIN(C10,G10) -> 180
B11: bcsstk01.mtx | C11: 18 | D11: 0.014 | E11: =(C11-$O11)/$O11 -> 0 | F11: =IF(C11=$O11,1,0) -> 1 | G11: 18 | H11: 0.015 | I11: =(G11-$O11)/$O11 -> 0 | J11: =IF(G11=$O11,1,0) -> 1 | O11: =MIN(C11,G11) -> 18
B12: bp_0.mtx | C12: 349 | D12: 10.457 | E12: =(C12-$O12)/$O12 -> 0.048048048 | F12: =IF(C12=$O12,1,0) -> 0 | G12: 333 | H12: 11.929 | I12: =(G12-$O12)/$O12 -> 0 | J12: =IF(G12=$O12,1,0) -> 1 | O12: =MIN(C12,G12) -> 333
B13: can_161.mtx | C13: 57 | D13: 0.061999999 | E13: =(C13-$O13)/$O13 -> 0 | F13: =IF(C13=$O13,1,0) -> 1 | G13: 57 | H13: 0.064000003 | I13: =(G13-$O13)/$O13 -> 0 | J13: =IF(G13=$O13,1,0) -> 1 | O13: =MIN(C13,G13) -> 57
B14: cavity03.mtx | C14: 26 | D14: 4.5830002 | E14: =(C14-$O14)/$O14 -> 0 | F14: =IF(C14=$O14,1,0) -> 1 | G14: 26 | H14: 4.698 | I14: =(G14-$O14)/$O14 -> 0 | J14: =IF(G14=$O14,1,0) -> 1 | O14: =MIN(C14,G14) -> 26
B15: ck656.mtx | C15: 321 | D15: 59.396 | E15: =(C15-$O15)/$O15 -> 0.099315068 | F15: =IF(C15=$O15,1,0) -> 0 | G15: 292 | H15: 36.973 | I15: =(G15-$O15)/$O15 -> 0 | J15: =IF(G15=$O15,1,0) -> 1 | O15: =MIN(C15,G15) -> 292
B16: dwt_361.mtx | C16: 152 | D16: 0.78799999 | E16: =(C16-$O16)/$O16 -> 0.020134228 | F16: =IF(C16=$O16,1,0) -> 0 | G16: 149 | H16: 0.43900001 | I16: =(G16-$O16)/$O16 -> 0 | J16: =IF(G16=$O16,1,0) -> 1 | O16: =MIN(C16,G16) -> 149
B17: dwt_59.mtx | C17: 43 | D17: 0.0060000001 | E17: =(C17-$O17)/$O17 -> 0 | F17: =IF(C17=$O17,1,0) -> 1 | G17: 43 | H17: 0.0049999999 | I17: =(G17-$O17)/$O17 -> 0 | J17: =IF(G17=$O17,1,0) -> 1 | O17: =MIN(C17,G17) -> 43
B18: e05r0200.mtx | C18: 18 | D18: 8.9119997 | E18: =(C18-$O18)/$O18 -> 0 | F18: =IF(C18=$O18,1,0) -> 1 | G18: 18 | H18: 9.2220001 | I18: =(G18-$O18)/$O18 -> 0 | J18: =IF(G18=$O18,1,0) -> 1 | O18: =MIN(C18,G18) -> 18
B19: fs_541_2.mtx | C19: 3 | D19: 12.59 | E19: =(C19-$O19)/$O19 -> 0 | F19: =IF(C19=$O19,1,0) -> 1 | G19: 3 | H19: 12.699 | I19: =(G19-$O19)/$O19 -> 0 | J19: =IF(G19=$O19,1,0) -> 1 | O19: =MIN(C19,G19) -> 3
... B33: will199.mtx | C33: 99 | D33: 0.17200001 | E33: =(C33-$O33)/$O33 -> 0.042105263 | F33: =IF(C33=$O33,1,0) -> 0 | G33: 95 | H33: 0.178 | I33: =(G33-$O33)/$O33 -> 0 | J33: =IF(G33=$O33,1,0) -> 1 | O33: =MIN(C33,G33) -> 95

Sheet Figure 6
B2: Iterations | C2: Avg. | D2: Time | E2: Dev. | F2: #best
B3: =C14 -> 10 | C3: =AVERAGE(C16:C41) -> 158.88462 | D3: =AVERAGE(D16:D41) -> 0.71919231 | E3: =AVERAGE(E16:E41) -> 0.020553445 | F3: =SUM(F16:F41) -> 14
B4: =G14 -> 20 | C4: =AVERAGE(G16:G41) -> 155.73077 | D4: =AVERAGE(H16:H41) -> 1.7096538 | E4: =AVERAGE(I16:I41) -> 0.0079765803 | F4: =SUM(J16:J41) -> 17
B5: =K14 -> 30 | C5: =AVERAGE(K16:K41) -> 155.11538 | D5: =AVERAGE(L16:L41) -> 2.4369615 | E5: =AVERAGE(M16:M41) -> 0.005791204 | F5: =SUM(N16:N41) -> 19
B6: =O14 -> 40 | C6: =AVERAGE(O16:O41) -> 154.92308 | D6: =AVERAGE(P16:P41) -> 2.8276154 | E6: =AVERAGE(Q16:Q41) -> 0.0048652781 | F6: =SUM(R16:R41) -> 21
B7: =S14 -> 50 | C7: =AVERAGE(S16:S41) -> 154.53846 | D7: =AVERAGE(T16:T41) -> 3.9617308 | E7: =AVERAGE(U16:U41) -> 0.001094539 | F7: =SUM(V16:V41) -> 22
B8: =W14 -> 60 | C8: =AVERAGE(W16:W41) -> 154.5 | D8: =AVERAGE(X16:X41) -> 4.2533462 | E8: =AVERAGE(Y16:Y41) -> 0.00048403839 | F8: =SUM(Z16:Z41) -> 23
B9: =AA14 -> 70 | C9: =AVERAGE(AA16:AA41) -> 154.38462 | D9: =AVERAGE(AB16:AB41) -> 4.712154 | E9: =AVERAGE(AC16:AC41) -> 0.00026343519 | F9: =SUM(AD16:AD41) -> 25
B10: =AE14 -> 80 | C10: =AVERAGE(AE16:AE41) -> 154.30769 | D10: =AVERAGE(AF16:AF41) -> 5.6006923 | E10: =AVERAGE(AG16:AG41) -> 0 | F10: =SUM(AH16:AH41) -> 26
B11: =AI14 -> 90 | C11: =AVERAGE(AI16:AI41) -> 154.30769 | D11: =AVERAGE(AJ16:AJ41) -> 5.9903462 | E11: =AVERAGE(AK16:AK41) -> 0 | F11: =SUM(AL16:AL41) -> 26
B12: =AM14 -> 100 | C12: =AVERAGE(AM16:AM41) -> 154.30769 | D12: =AVERAGE(AN16:AN41) -> 6.3805 | E12: =AVERAGE(AO16:AO41) -> 0 | F12: =SUM(AP16:AP41) -> 26
C14: 10 | G14: 20 | K14: 30 | O14: 40 | S14: 50 | W14: 60 | AA14: 70 | AE14: 80 | AI14: 90 | AM14: 100
B15: Instance | C15: OF | D15: Time | E15: Dev | F15: Best | G15: OF | H15: Time | I15: Dev | J15: Best | K15: OF | L15: Time | M15: Dev | N15: Best | O15: OF | P15: Time | Q15: Dev | R15: Best | S15: OF | T15: Time | U15: Dev | V15: Best | W15: OF | X15: Time | Y15: Dev | Z15: Best | AA15: OF | AB15: Time | AC15: Dev | AD15: Best | AE15: OF | AF15: Time | AG15: Dev | AH15: Best | AI15: OF | AJ15: Time | AK15: Dev | AL15: Best | AM15: OF | AN15: Time | AO15: Dev | AP15: Best | AR15: #best
B16: 662_bus.mtx | C16: 535 | D16: 0.35800001 | E16: =(C16-$AR16)/$AR16 -> 0.0056390977 | F16: =IF(C16=$AR16,1,0) -> 0 | G16: 534 | H16: 0.44299999 | I16: =(G16-$AR16)/$AR16 -> 0.0037593985 | J16: =IF(G16=$AR16,1,0) -> 0 | K16: 534 | L16: 0.523 | M16: =(K16-$AR16)/$AR16 -> 0.0037593985 | N16: =IF(K16=$AR16,1,0) -> 0 | O16: 534 | P16: 0.61900002 | Q16: =(O16-$AR16)/$AR16 -> 0.0037593985 | R16: =IF(O16=$AR16,1,0) -> 0 | S16: 534 | T16: 0.71399999 | U16: =(S16-$AR16)/$AR16 -> 0.0037593985 | V16: =IF(S16=$AR16,1,0) -> 0 | W16: 534 | X16: 0.91100001 | Y16: =(W16-$AR16)/$AR16 -> 0.0037593985 | Z16: =IF(W16=$AR16,1,0) -> 0 | AA16: 532 | AB16: 1.652 | AC16: =(AA16-$AR16)/$AR16 -> 0 | AD16: =IF(AA16=$AR16,1,0) -> 1 | AE16: 532 | AF16: 1.704 | AG16: =(AE16-$AR16)/$AR16 -> 0 | AH16: =IF(AE16=$AR16,1,0) -> 1 | AI16: 532 | AJ16: 1.788 | AK16: =(AI16-$AR16)/$AR16 -> 0 | AL16: =IF(AI16=$AR16,1,0) -> 1 | AM16: 532 | AN16: 1.874 | AO16: =(AM16-$AR16)/$AR16 -> 0 | AP16: =IF(AM16=$AR16,1,0) -> 1 | AR16: =MIN(C16,G16,K16,O16,S16,W16,AA16,AE16,AI16,AM16) -> 532
B17: ash331.mtx | C17: 161 | D17: 0.061000001 | E17: =(C17-$AR17)/$AR17 -> 0 | F17: =IF(C17=$AR17,1,0) -> 1 | G17: 161 | H17: 0.07 | I17: =(G17-$AR17)/$AR17 -> 0 | J17: =IF(G17=$AR17,1,0) -> 1 | K17: 161 | L17: 0.086999997 | M17: =(K17-$AR17)/$AR17 -> 0 | N17: =IF(K17=$AR17,1,0) -> 1 | O17: 161 | P17: 0.105 | Q17: =(O17-$AR17)/$AR17 -> 0 | R17: =IF(O17=$AR17,1,0) -> 1 | S17: 161 | T17: 0.121 | U17: =(S17-$AR17)/$AR17 -> 0 | V17: =IF(S17=$AR17,1,0) -> 1 | W17: 161 | X17: 0.133 | Y17: =(W17-$AR17)/$AR17 -> 0 | Z17: =IF(W17=$AR17,1,0) -> 1 | AA17: 161 | AB17: 0.15000001 | AC17: =(AA17-$AR17)/$AR17 -> 0 | AD17: =IF(AA17=$AR17,1,0) -> 1 | AE17: 161 | AF17: 0.16500001 | AG17: =(AE17-$AR17)/$AR17 -> 0 | AH17: =IF(AE17=$AR17,1,0) -> 1 | AI17: 161 | AJ17: 0.182 | AK17: =(AI17-$AR17)/$AR17 -> 0 | AL17: =IF(AI17=$AR17,1,0) -> 1 | AM17: 161 | AN17: 0.198 | AO17: =(AM17-$AR17)/$AR17 -> 0 | AP17: =IF(AM17=$AR17,1,0) -> 1 | AR17: =MIN(C17,G17,K17,O17,S17,W17,AA17,AE17,AI17,AM17) -> 161
B18: bcspwr04.mtx | C18: 180 | D18: 0.133 | E18: =(C18-$AR18)/$AR18 -> 0 | F18: =IF(C18=$AR18,1,0) -> 1 | G18: 180 | H18: 0.163 | I18: =(G18-$AR18)/$AR18 -> 0 | J18: =IF(G18=$AR18,1,0) -> 1 | K18: 180 | L18: 0.2 | M18: =(K18-$AR18)/$AR18 -> 0 | N18: =IF(K18=$AR18,1,0) -> 1 | O18: 180 | P18: 0.23199999 | Q18: =(O18-$AR18)/$AR18 -> 0 | R18: =IF(O18=$AR18,1,0) -> 1 | S18: 180 | T18: 0.26499999 | U18: =(S18-$AR18)/$AR18 -> 0 | V18: =IF(S18=$AR18,1,0) -> 1 | W18: 180 | X18: 0.28099999 | Y18: =(W18-$AR18)/$AR18 -> 0 | Z18: =IF(W18=$AR18,1,0) -> 1 | AA18: 180 | AB18: 0.31799999 | AC18: =(AA18-$AR18)/$AR18 -> 0 | AD18: =IF(AA18=$AR18,1,0) -> 1 | AE18: 180 | AF18: 0.35600001 | AG18: =(AE18-$AR18)/$AR18 -> 0 | AH18: =IF(AE18=$AR18,1,0) -> 1 | AI18: 180 | AJ18: 0.389 | AK18: =(AI18-$AR18)/$AR18 -> 0 | AL18: =IF(AI18=$AR18,1,0) -> 1 | AM18: 180 | AN18: 0.43700001 | AO18: =(AM18-$AR18)/$AR18 -> 0 | AP18: =IF(AM18=$AR18,1,0) -> 1 | AR18: =MIN(C18,G18,K18,O18,S18,W18,AA18,AE18,AI18,AM18) -> 180
B19: bcsstk01.mtx | C19: 20 | D19: 0.0020000001 | E19: =(C19-$AR19)/$AR19 -> 0.11111111 | F19: =IF(C19=$AR19,1,0) -> 0 | G19: 18 | H19: 0.0060000001 | I19: =(G19-$AR19)/$AR19 -> 0 | J19: =IF(G19=$AR19,1,0) -> 1 | K19: 18 | L19: 0.0070000002 | M19: =(K19-$AR19)/$AR19 -> 0 | N19: =IF(K19=$AR19,1,0) -> 1 | O19: 18 | P19: 0.0089999996 | Q19: =(O19-$AR19)/$AR19 -> 0 | R19: =IF(O19=$AR19,1,0) -> 1 | S19: 18 | T19: 0.011 | U19: =(S19-$AR19)/$AR19 -> 0 | V19: =IF(S19=$AR19,1,0) -> 1 | W19: 18 | X19: 0.011 | Y19: =(W19-$AR19)/$AR19 -> 0 | Z19: =IF(W19=$AR19,1,0) -> 1 | AA19: 18 | AB19: 0.013 | AC19: =(AA19-$AR19)/$AR19 -> 0 | AD19: =IF(AA19=$AR19,1,0) -> 1 | AE19: 18 | AF19: 0.015 | AG19: =(AE19-$AR19)/$AR19 -> 0 | AH19: =IF(AE19=$AR19,1,0) -> 1 | AI19: 18 | AJ19: 0.017000001 | AK19: =(AI19-$AR19)/$AR19 -> 0 | AL19: =IF(AI19=$AR19,1,0) -> 1 | AM19: 18 | AN19: 0.017999999 | AO19: =(AM19-$AR19)/$AR19 -> 0 | AP19: =IF(AM19=$AR19,1,0) -> 1 | AR19: =MIN(C19,G19,K19,O19,S19,W19,AA19,AE19,AI19,AM19) -> 18
B20: bp_0.mtx | C20: 335 | D20: 2.9990001 | E20: =(C20-$AR20)/$AR20 -> 0.006006006 | F20: =IF(C20=$AR20,1,0) -> 0 | G20: 333 | H20: 6.881 | I20: =(G20-$AR20)/$AR20 -> 0 | J20: =IF(G20=$AR20,1,0) -> 1 | K20: 333 | L20: 7.8969998 | M20: =(K20-$AR20)/$AR20 -> 0 | N20: =IF(K20=$AR20,1,0) -> 1 | O20: 333 | P20: 8.6829996 | Q20: =(O20-$AR20)/$AR20 -> 0 | R20: =IF(O20=$AR20,1,0) -> 1 | S20: 333 | T20: 9.6739998 | U20: =(S20-$AR20)/$AR20 -> 0 | V20: =IF(S20=$AR20,1,0) -> 1 | W20: 333 | X20: 10.032 | Y20: =(W20-$AR20)/$AR20 -> 0 | Z20: =IF(W20=$AR20,1,0) -> 1 | AA20: 333 | AB20: 11.104 | AC20: =(AA20-$AR20)/$AR20 -> 0 | AD20: =IF(AA20=$AR20,1,0) -> 1 | AE20: 333 | AF20: 11.929 | AG20: =(AE20-$AR20)/$AR20 -> 0 | AH20: =IF(AE20=$AR20,1,0) -> 1 | AI20: 333 | AJ20: 12.841 | AK20: =(AI20-$AR20)/$AR20 -> 0 | AL20: =IF(AI20=$AR20,1,0) -> 1 | AM20: 333 | AN20: 13.764 | AO20: =(AM20-$AR20)/$AR20 -> 0 | AP20: =IF(AM20=$AR20,1,0) -> 1 | AR20: =MIN(C20,G20,K20,O20,S20,W20,AA20,AE20,AI20,AM20) -> 333
B21: can_161.mtx | C21: 57 | D21: 0.0089999996 | E21: =(C21-$AR21)/$AR21 -> 0 | F21: =IF(C21=$AR21,1,0) -> 1 | G21: 57 | H21: 0.017999999 | I21: =(G21-$AR21)/$AR21 -> 0 | J21: =IF(G21=$AR21,1,0) -> 1 | K21: 57 | L21: 0.025 | M21: =(K21-$AR21)/$AR21 -> 0 | N21: =IF(K21=$AR21,1,0) -> 1 | O21: 57 | P21: 0.033 | Q21: =(O21-$AR21)/$AR21 -> 0 | R21: =IF(O21=$AR21,1,0) -> 1 | S21: 57 | T21: 0.041000001 | U21: =(S21-$AR21)/$AR21 -> 0 | V21: =IF(S21=$AR21,1,0) -> 1 | W21: 57 | X21: 0.046999998 | Y21: =(W21-$AR21)/$AR21 -> 0 | Z21: =IF(W21=$AR21,1,0) -> 1 | AA21: 57 | AB21: 0.056000002 | AC21: =(AA21-$AR21)/$AR21 -> 0 | AD21: =IF(AA21=$AR21,1,0) -> 1 | AE21: 57 | AF21: 0.064000003 | AG21: =(AE21-$AR21)/$AR21 -> 0 | AH21: =IF(AE21=$AR21,1,0) -> 1 | AI21: 57 | AJ21: 0.072999999 | AK21: =(AI21-$AR21)/$AR21 -> 0 | AL21: =IF(AI21=$AR21,1,0) -> 1 | AM21: 57 | AN21: 0.079999998 | AO21: =(AM21-$AR21)/$AR21 -> 0 | AP21: =IF(AM21=$AR21,1,0) -> 1 | AR21: =MIN(C21,G21,K21,O21,S21,W21,AA21,AE21,AI21,AM21) -> 57
B22: cavity03.mtx | C22: 26 | D22: 0.57599998 | E22: =(C22-$AR22)/$AR22 -> 0 | F22: =IF(C22=$AR22,1,0) -> 1 | G22: 26 | H22: 1.149 | I22: =(G22-$AR22)/$AR22 -> 0 | J22: =IF(G22=$AR22,1,0) -> 1 | K22: 26 | L22: 1.716 | M22: =(K22-$AR22)/$AR22 -> 0 | N22: =IF(K22=$AR22,1,0) -> 1 | O22: 26 | P22: 2.3670001 | Q22: =(O22-$AR22)/$AR22 -> 0 | R22: =IF(O22=$AR22,1,0) -> 1 | S22: 26 | T22: 2.813 | U22: =(S22-$AR22)/$AR22 -> 0 | V22: =IF(S22=$AR22,1,0) -> 1 | W22: 26 | X22: 3.4909999 | Y22: =(W22-$AR22)/$AR22 -> 0 | Z22: =IF(W22=$AR22,1,0) -> 1 | AA22: 26 | AB22: 3.9860001 | AC22: =(AA22-$AR22)/$AR22 -> 0 | AD22: =IF(AA22=$AR22,1,0) -> 1 | AE22: 26 | AF22: 4.698 | AG22: =(AE22-$AR22)/$AR22 -> 0 | AH22: =IF(AE22=$AR22,1,0) -> 1 | AI22: 26 | AJ22: 5.3439999 | AK22: =(AI22-$AR22)/$AR22 -> 0 | AL22: =IF(AI22=$AR22,1,0) -> 1 | AM22: 26 | AN22: 5.9710002 | AO22: =(AM22-$AR22)/$AR22 -> 0 | AP22: =IF(AM22=$AR22,1,0) -> 1 | AR22: =MIN(C22,G22,K22,O22,S22,W22,AA22,AE22,AI22,AM22) -> 26
B23: ck656.mtx | C23: 300 | D23: 3.9560001 | E23: =(C23-$AR23)/$AR23 -> 0.02739726 | F23: =IF(C23=$AR23,1,0) -> 0 | G23: 294 | H23: 12.672 | I23: =(G23-$AR23)/$AR23 -> 0.0068493151 | J23: =IF(G23=$AR23,1,0) -> 0 | K23: 294 | L23: 14.666 | M23: =(K23-$AR23)/$AR23 -> 0.0068493151 | N23: =IF(K23=$AR23,1,0) -> 0 | O23: 294 | P23: 16.454 | Q23: =(O23-$AR23)/$AR23 -> 0.0068493151 | R23: =IF(O23=$AR23,1,0) -> 0 | S23: 294 | T23: 18.259001 | U23: =(S23-$AR23)/$AR23 -> 0.0068493151 | V23: =IF(S23=$AR23,1,0) -> 0 | W23: 294 | X23: 19.636 | Y23: =(W23-$AR23)/$AR23 -> 0.0068493151 | Z23: =IF(W23=$AR23,1,0) -> 0 | AA23: 294 | AB23: 21.513 | AC23: =(AA23-$AR23)/$AR23 -> 0.0068493151 | AD23: =IF(AA23=$AR23,1,0) -> 0 | AE23: 292 | AF23: 36.973 | AG23: =(AE23-$AR23)/$AR23 -> 0 | AH23: =IF(AE23=$AR23,1,0) -> 1 | AI23: 292 | AJ23: 38.844002 | AK23: =(AI23-$AR23)/$AR23 -> 0 | AL23: =IF(AI23=$AR23,1,0) -> 1 | AM23: 292 | AN23: 40.669998 | AO23: =(AM23-$AR23)/$AR23 -> 0 | AP23: =IF(AM23=$AR23,1,0) -> 1 | AR23: =MIN(C23,G23,K23,O23,S23,W23,AA23,AE23,AI23,AM23) -> 292
B24: dwt_361.mtx | C24: 149 | D24: 0.152 | E24: =(C24-$AR24)/$AR24 -> 0 | F24: =IF(C24=$AR24,1,0) -> 1 | G24: 149 | H24: 0.18799999 | I24: =(G24-$AR24)/$AR24 -> 0 | J24: =IF(G24=$AR24,1,0) -> 1 | K24: 149 | L24: 0.23199999 | M24: =(K24-$AR24)/$AR24 -> 0 | N24: =IF(K24=$AR24,1,0) -> 1 | O24: 149 | P24: 0.273 | Q24: =(O24-$AR24)/$AR24 -> 0 | R24: =IF(O24=$AR24,1,0) -> 1 | S24: 149 | T24: 0.315 | U24: =(S24-$AR24)/$AR24 -> 0 | V24: =IF(S24=$AR24,1,0) -> 1 | W24: 149 | X24: 0.352 | Y24: =(W24-$AR24)/$AR24 -> 0 | Z24: =IF(W24=$AR24,1,0) -> 1 | AA24: 149 | AB24: 0.39500001 | AC24: =(AA24-$AR24)/$AR24 -> 0 | AD24: =IF(AA24=$AR24,1,0) -> 1 | AE24: 149 | AF24: 0.43900001 | AG24: =(AE24-$AR24)/$AR24 -> 0 | AH24: =IF(AE24=$AR24,1,0) -> 1 | AI24: 149 | AJ24: 0.48300001 | AK24: =(AI24-$AR24)/$AR24 -> 0 | AL24: =IF(AI24=$AR24,1,0) -> 1 | AM24: 149 | AN24: 0.52399999 | AO24: =(AM24-$AR24)/$AR24 -> 0 | AP24: =IF(AM24=$AR24,1,0) -> 1 | AR24: =MIN(C24,G24,K24,O24,S24,W24,AA24,AE24,AI24,AM24) -> 149
B25: dwt_59.mtx | C25: 43 | D25: 0.001 | E25: =(C25-$AR25)/$AR25 -> 0 | F25: =IF(C25=$AR25,1,0) -> 1 | G25: 43 | H25: 0.0020000001 | I25: =(G25-$AR25)/$AR25 -> 0 | J25: =IF(G25=$AR25,1,0) -> 1 | K25: 43 | L25: 0.0020000001 | M25: =(K25-$AR25)/$AR25 -> 0 | N25: =IF(K25=$AR25,1,0) -> 1 | O25: 43 | P25: 0.003 | Q25: =(O25-$AR25)/$AR25 -> 0 | R25: =IF(O25=$AR25,1,0) -> 1 | S25: 43 | T25: 0.003 | U25: =(S25-$AR25)/$AR25 -> 0 | V25: =IF(S25=$AR25,1,0) -> 1 | W25: 43 | X25: 0.003 | Y25: =(W25-$AR25)/$AR25 -> 0 | Z25: =IF(W25=$AR25,1,0) -> 1 | AA25: 43 | AB25: 0.0040000002 | AC25: =(AA25-$AR25)/$AR25 -> 0 | AD25: =IF(AA25=$AR25,1,0) -> 1 | AE25: 43 | AF25: 0.0049999999 | AG25: =(AE25-$AR25)/$AR25 -> 0 | AH25: =IF(AE25=$AR25,1,0) -> 1 | AI25: 43 | AJ25: 0.0049999999 | AK25: =(AI25-$AR25)/$AR25 -> 0 | AL25: =IF(AI25=$AR25,1,0) -> 1 | AM25: 43 | AN25: 0.0049999999 | AO25: =(AM25-$AR25)/$AR25 -> 0 | AP25: =IF(AM25=$AR25,1,0) -> 1 | AR25: =MIN(C25,G25,K25,O25,S25,W25,AA25,AE25,AI25,AM25) -> 43
B26: e05r0200.mtx | C26: 18 | D26: 1.16 | E26: =(C26-$AR26)/$AR26 -> 0 | F26: =IF(C26=$AR26,1,0) -> 1 | G26: 18 | H26: 2.355 | I26: =(G26-$AR26)/$AR26 -> 0 | J26: =IF(G26=$AR26,1,0) -> 1 | K26: 18 | L26: 3.526 | M26: =(K26-$AR26)/$AR26 -> 0 | N26: =IF(K26=$AR26,1,0) -> 1 | O26: 18 | P26: 4.6630001 | Q26: =(O26-$AR26)/$AR26 -> 0 | R26: =IF(O26=$AR26,1,0) -> 1 | S26: 18 | T26: 5.8070002 | U26: =(S26-$AR26)/$AR26 -> 0 | V26: =IF(S26=$AR26,1,0) -> 1 | W26: 18 | X26: 6.915 | Y26: =(W26-$AR26)/$AR26 -> 0 | Z26: =IF(W26=$AR26,1,0) -> 1 | AA26: 18 | AB26: 8.118 | AC26: =(AA26-$AR26)/$AR26 -> 0 | AD26: =IF(AA26=$AR26,1,0) -> 1 | AE26: 18 | AF26: 9.2220001 | AG26: =(AE26-$AR26)/$AR26 -> 0 | AH26: =IF(AE26=$AR26,1,0) -> 1 | AI26: 18 | AJ26: 10.049 | AK26: =(AI26-$AR26)/$AR26 -> 0 | AL26: =IF(AI26=$AR26,1,0) -> 1 | AM26: 18 | AN26: 11.46 | AO26: =(AM26-$AR26)/$AR26 -> 0 | AP26: =IF(AM26=$AR26,1,0) -> 1 | AR26: =MIN(C26,G26,K26,O26,S26,W26,AA26,AE26,AI26,AM26) -> 18
B27: fs_541_2.mtx | C27: 3 | D27: 1.891 | E27: =(C27-$AR27)/$AR27 -> 0 | F27: =IF(C27=$AR27,1,0) -> 1 | G27: 3 | H27: 3.187 | I27: =(G27-$AR27)/$AR27 -> 0 | J27: =IF(G27=$AR27,1,0) -> 1 | K27: 3 | L27: 4.8499999 | M27: =(K27-$AR27)/$AR27 -> 0 | N27: =IF(K27=$AR27,1,0) -> 1 | O27: 3 | P27: 6.5780001 | Q27: =(O27-$AR27)/$AR27 -> 0 | R27: =IF(O27=$AR27,1,0) -> 1 | S27: 3 | T27: 8.0690002 | U27: =(S27-$AR27)/$AR27 -> 0 | V27: =IF(S27=$AR27,1,0) -> 1 | W27: 3 | X27: 9.5450001 | Y27: =(W27-$AR27)/$AR27 -> 0 | Z27: =IF(W27=$AR27,1,0) -> 1 | AA27: 3 | AB27: 11.264 | AC27: =(AA27-$AR27)/$AR27 -> 0 | AD27: =IF(AA27=$AR27,1,0) -> 1 | AE27: 3 | AF27: 12.699 | AG27: =(AE27-$AR27)/$AR27 -> 0 | AH27: =IF(AE27=$AR27,1,0) -> 1 | AI27: 3 | AJ27: 14.461 | AK27: =(AI27-$AR27)/$AR27 -> 0 | AL27: =IF(AI27=$AR27,1,0) -> 1 | AM27: 3 | AN27: 16.018 | AO27: =(AM27-$AR27)/$AR27 -> 0 | AP27: =IF(AM27=$AR27,1,0) -> 1 | AR27: =MIN(C27,G27,K27,O27,S27,W27,AA27,AE27,AI27,AM27) -> 3
... B41: will199.mtx | C41: 98 | D41: 0.035 | E41: =(C41-$AR41)/$AR41 -> 0.031578947 | F41: =IF(C41=$AR41,1,0) -> 0 | G41: 98 | H41: 0.054000001 | I41: =(G41-$AR41)/$AR41 -> 0.031578947 | J41: =IF(G41=$AR41,1,0) -> 0 | K41: 95 | L41: 0.101 | M41: =(K41-$AR41)/$AR41 -> 0 | N41: =IF(K41=$AR41,1,0) -> 1 | O41: 95 | P41: 0.116 | Q41: =(O41-$AR41)/$AR41 -> 0 | R41: =IF(O41=$AR41,1,0) -> 1 | S41: 95 | T41: 0.133 | U41: =(S41-$AR41)/$AR41 -> 0 | V41: =IF(S41=$AR41,1,0) -> 1 | W41: 95 | X41: 0.145 | Y41: =(W41-$AR41)/$AR41 -> 0 | Z41: =IF(W41=$AR41,1,0) -> 1 | AA41: 95 | AB41: 0.16 | AC41: =(AA41-$AR41)/$AR41 -> 0 | AD41: =IF(AA41=$AR41,1,0) -> 1 | AE41: 95 | AF41: 0.178 | AG41: =(AE41-$AR41)/$AR41 -> 0 | AH41: =IF(AE41=$AR41,1,0) -> 1 | AI41: 95 | AJ41: 0.19 | AK41: =(AI41-$AR41)/$AR41 -> 0 | AL41: =IF(AI41=$AR41,1,0) -> 1 | AM41: 95 | AN41: 0.205 | AO41: =(AM41-$AR41)/$AR41 -> 0 | AP41: =IF(AM41=$AR41,1,0) -> 1 | AR41: =MIN(C41,G41,K41,O41,S41,W41,AA41,AE41,AI41,AM41) -> 95

Sheet Table 4
B2: Strategie | C2: Avg. | D2: Time | E2: Dev. | F2: #best
B3: =C6 -> Last accepted solution | C3: =AVERAGE(C8:C33) -> 156.46154 | D3: =AVERAGE(D8:D33) -> 5.9683077 | E3: =AVERAGE(E8:E33) -> 0.0070077837 | F3: =SUM(F8:F33) -> 18
B4: =G6 -> Best solution | C4: =AVERAGE(G8:G33) -> 154.30769 | D4: =AVERAGE(H8:H33) -> 5.6006923 | E4: =AVERAGE(I8:I33) -> 0.0033787635 | F4: =SUM(J8:J33) -> 22
C6: Last accepted solution | G6: Best solution
B7: Instance | C7: OF | D7: Time | E7: Dev | F7: Best | G7: OF | H7: Time | I7: Dev | J7: Best | O7: #best
B8: 662_bus.mtx | C8: 535 | D8: 2.515 | E8: =(C8-$O8)/$O8 -> 0.0056390977 | F8: =IF(C8=$O8,1,0) -> 0 | G8: 532 | H8: 1.704 | I8: =(G8-$O8)/$O8 -> 0 | J8: =IF(G8=$O8,1,0) -> 1 | O8: =MIN(C8,G8) -> 532
B9: ash331.mtx | C9: 160 | D9: 0.374 | E9: =(C9-$O9)/$O9 -> 0 | F9: =IF(C9=$O9,1,0) -> 1 | G9: 161 | H9: 0.16500001 | I9: =(G9-$O9)/$O9 -> 0.00625 | J9: =IF(G9=$O9,1,0) -> 0 | O9: =MIN(C9,G9) -> 160
B10: bcspwr04.mtx | C10: 181 | D10: 0.678 | E10: =(C10-$O10)/$O10 -> 0.0055555556 | F10: =IF(C10=$O10,1,0) -> 0 | G10: 180 | H10: 0.35600001 | I10: =(G10-$O10)/$O10 -> 0 | J10: =IF(G10=$O10,1,0) -> 1 | O10: =MIN(C10,G10) -> 180
B11: bcsstk01.mtx | C11: 18 | D11: 0.019 | E11: =(C11-$O11)/$O11 -> 0 | F11: =IF(C11=$O11,1,0) -> 1 | G11: 18 | H11: 0.015 | I11: =(G11-$O11)/$O11 -> 0 | J11: =IF(G11=$O11,1,0) -> 1 | O11: =MIN(C11,G11) -> 18
B12: bp_0.mtx | C12: 331 | D12: 29.151 | E12: =(C12-$O12)/$O12 -> 0 | F12: =IF(C12=$O12,1,0) -> 1 | G12: 333 | H12: 11.929 | I12: =(G12-$O12)/$O12 -> 0.0060422961 | J12: =IF(G12=$O12,1,0) -> 0 | O12: =MIN(C12,G12) -> 331
B13: can_161.mtx | C13: 57 | D13: 0.086 | E13: =(C13-$O13)/$O13 -> 0 | F13: =IF(C13=$O13,1,0) -> 1 | G13: 57 | H13: 0.064000003 | I13: =(G13-$O13)/$O13 -> 0 | J13: =IF(G13=$O13,1,0) -> 1 | O13: =MIN(C13,G13) -> 57
B14: cavity03.mtx | C14: 26 | D14: 6.299 | E14: =(C14-$O14)/$O14 -> 0 | F14: =IF(C14=$O14,1,0) -> 1 | G14: 26 | H14: 4.698 | I14: =(G14-$O14)/$O14 -> 0 | J14: =IF(G14=$O14,1,0) -> 1 | O14: =MIN(C14,G14) -> 26
B15: ck656.mtx | C15: 299 | D15: 27.425 | E15: =(C15-$O15)/$O15 -> 0.023972603 | F15: =IF(C15=$O15,1,0) -> 0 | G15: 292 | H15: 36.973 | I15: =(G15-$O15)/$O15 -> 0 | J15: =IF(G15=$O15,1,0) -> 1 | O15: =MIN(C15,G15) -> 292
B16: dwt_361.mtx | C16: 152 | D16: 0.592 | E16: =(C16-$O16)/$O16 -> 0.020134228 | F16: =IF(C16=$O16,1,0) -> 0 | G16: 149 | H16: 0.43900001 | I16: =(G16-$O16)/$O16 -> 0 | J16: =IF(G16=$O16,1,0) -> 1 | O16: =MIN(C16,G16) -> 149
B17: dwt_59.mtx | C17: 43 | D17: 0.007 | E17: =(C17-$O17)/$O17 -> 0 | F17: =IF(C17=$O17,1,0) -> 1 | G17: 43 | H17: 0.0049999999 | I17: =(G17-$O17)/$O17 -> 0 | J17: =IF(G17=$O17,1,0) -> 1 | O17: =MIN(C17,G17) -> 43
B18: e05r0200.mtx | C18: 18 | D18: 12.489 | E18: =(C18-$O18)/$O18 -> 0 | F18: =IF(C18=$O18,1,0) -> 1 | G18: 18 | H18: 9.2220001 | I18: =(G18-$O18)/$O18 -> 0 | J18: =IF(G18=$O18,1,0) -> 1 | O18: =MIN(C18,G18) -> 18
B19: fs_541_2.mtx | C19: 3 | D19: 16.813 | E19: =(C19-$O19)/$O19 -> 0 | F19: =IF(C19=$O19,1,0) -> 1 | G19: 3 | H19: 12.699 | I19: =(G19-$O19)/$O19 -> 0 | J19: =IF(G19=$O19,1,0) -> 1 | O19: =MIN(C19,G19) -> 3
... B33: will199.mtx | C33: 90 | D33: 0.335 | E33: =(C33-$O33)/$O33 -> 0 | F33: =IF(C33=$O33,1,0) -> 1 | G33: 95 | H33: 0.178 | I33: =(G33-$O33)/$O33 -> 0.055555556 | J33: =IF(G33=$O33,1,0) -> 0 | O33: =MIN(C33,G33) -> 90

Sheet Figure 7
B2: Algorithm | C2: Avg. | D2: Time | E2: Dev. | F2: #best
B3: =C7 -> Constructive | C3: =AVERAGE(C9:C34) -> 194.46154 | D3: =AVERAGE(D9:D34) -> 0.00065384618 | E3: =AVERAGE(E9:E34) -> 0.19936831 | F3: =SUM(F9:F34) -> 4
B4: =G7 -> Local Search | C4: =AVERAGE(G9:G34) -> 170.46154 | D4: =AVERAGE(H9:H34) -> 0.033807692 | E4: =AVERAGE(I9:I34) -> 0.095220149 | F4: =SUM(J9:J34) -> 7
B5: =K7 -> ILS | C5: =AVERAGE(K9:K34) -> 154.30769 | D5: =AVERAGE(L9:L34) -> 5.6006923 | E5: =AVERAGE(M9:M34) -> 0 | F5: =SUM(N9:N34) -> 26
C7: Constructive | G7: Local Search | K7: ILS
B8: Instance | C8: OF | D8: Time | E8: Dev | F8: Best | G8: OF | H8: Time | I8: Dev | J8: Best | K8: OF | L8: Time | M8: Dev | N8: Best | S8: #best
B9: 662_bus.mtx | C9: 603 | D9: 0.003 | E9: =(C9-$S9)/$S9 -> 0.13345865 | F9: =IF(C9=$S9,1,0) -> 0 | G9: 545 | H9: 0.050999999 | I9: =(G9-$S9)/$S9 -> 0.02443609 | J9: =IF(G9=$S9,1,0) -> 0 | K9: 532 | L9: 1.704 | M9: =(K9-$S9)/$S9 -> 0 | N9: =IF(K9=$S9,1,0) -> 1 | S9: =MIN(C9,G9,K9) -> 532
B10: ash331.mtx | C10: 197 | D10: 0.001 | E10: =(C10-$S10)/$S10 -> 0.22360248 | F10: =IF(C10=$S10,1,0) -> 0 | G10: 186 | H10: 0.0020000001 | I10: =(G10-$S10)/$S10 -> 0.1552795 | J10: =IF(G10=$S10,1,0) -> 0 | K10: 161 | L10: 0.16500001 | M10: =(K10-$S10)/$S10 -> 0 | N10: =IF(K10=$S10,1,0) -> 1 | S10: =MIN(C10,G10,K10) -> 161
B11: bcspwr04.mtx | C11: 208 | D11: 0.001 | E11: =(C11-$S11)/$S11 -> 0.15555556 | F11: =IF(C11=$S11,1,0) -> 0 | G11: 184 | H11: 0.0089999996 | I11: =(G11-$S11)/$S11 -> 0.022222222 | J11: =IF(G11=$S11,1,0) -> 0 | K11: 180 | L11: 0.35600001 | M11: =(K11-$S11)/$S11 -> 0 | N11: =IF(K11=$S11,1,0) -> 1 | S11: =MIN(C11,G11,K11) -> 180
B12: bcsstk01.mtx | C12: 23 | D12: 0 | E12: =(C12-$S12)/$S12 -> 0.27777778 | F12: =IF(C12=$S12,1,0) -> 0 | G12: 20 | H12: 0 | I12: =(G12-$S12)/$S12 -> 0.11111111 | J12: =IF(G12=$S12,1,0) -> 0 | K12: 18 | L12: 0.015 | M12: =(K12-$S12)/$S12 -> 0 | N12: =IF(K12=$S12,1,0) -> 1 | S12: =MIN(C12,G12,K12) -> 18
B13: bp_0.mtx | C13: 421 | D13: 0.0020000001 | E13: =(C13-$S13)/$S13 -> 0.26426426 | F13: =IF(C13=$S13,1,0) -> 0 | G13: 347 | H13: 0.31299999 | I13: =(G13-$S13)/$S13 -> 0.042042042 | J13: =IF(G13=$S13,1,0) -> 0 | K13: 333 | L13: 11.929 | M13: =(K13-$S13)/$S13 -> 0 | N13: =IF(K13=$S13,1,0) -> 1 | S13: =MIN(C13,G13,K13) -> 333
B14: can_161.mtx | C14: 81 | D14: 0 | E14: =(C14-$S14)/$S14 -> 0.42105263 | F14: =IF(C14=$S14,1,0) -> 0 | G14: 71 | H14: 0.001 | I14: =(G14-$S14)/$S14 -> 0.24561404 | J14: =IF(G14=$S14,1,0) -> 0 | K14: 57 | L14: 0.064000003 | M14: =(K14-$S14)/$S14 -> 0 | N14: =IF(K14=$S14,1,0) -> 1 | S14: =MIN(C14,G14,K14) -> 57
B15: cavity03.mtx | C15: 26 | D15: 0.001 | E15: =(C15-$S15)/$S15 -> 0 | F15: =IF(C15=$S15,1,0) -> 1 | G15: 26 | H15: 0.027000001 | I15: =(G15-$S15)/$S15 -> 0 | J15: =IF(G15=$S15,1,0) -> 1 | K15: 26 | L15: 4.698 | M15: =(K15-$S15)/$S15 -> 0 | N15: =IF(K15=$S15,1,0) -> 1 | S15: =MIN(C15,G15,K15) -> 26
B16: ck656.mtx | C16: 337 | D16: 0.001 | E16: =(C16-$S16)/$S16 -> 0.15410959 | F16: =IF(C16=$S16,1,0) -> 0 | G16: 329 | H16: 0.024 | I16: =(G16-$S16)/$S16 -> 0.12671233 | J16: =IF(G16=$S16,1,0) -> 0 | K16: 292 | L16: 36.973 | M16: =(K16-$S16)/$S16 -> 0 | N16: =IF(K16=$S16,1,0) -> 1 | S16: =MIN(C16,G16,K16) -> 292
B17: dwt_361.mtx | C17: 182 | D17: 0.001 | E17: =(C17-$S17)/$S17 -> 0.22147651 | F17: =IF(C17=$S17,1,0) -> 0 | G17: 165 | H17: 0.001 | I17: =(G17-$S17)/$S17 -> 0.10738255 | J17: =IF(G17=$S17,1,0) -> 0 | K17: 149 | L17: 0.43900001 | M17: =(K17-$S17)/$S17 -> 0 | N17: =IF(K17=$S17,1,0) -> 1 | S17: =MIN(C17,G17,K17) -> 149
B18: dwt_59.mtx | C18: 51 | D18: 0 | E18: =(C18-$S18)/$S18 -> 0.18604651 | F18: =IF(C18=$S18,1,0) -> 0 | G18: 48 | H18: 0 | I18: =(G18-$S18)/$S18 -> 0.11627907 | J18: =IF(G18=$S18,1,0) -> 0 | K18: 43 | L18: 0.0049999999 | M18: =(K18-$S18)/$S18 -> 0 | N18: =IF(K18=$S18,1,0) -> 1 | S18: =MIN(C18,G18,K18) -> 43
B19: e05r0200.mtx | C19: 18 | D19: 0.001 | E19: =(C19-$S19)/$S19 -> 0 | F19: =IF(C19=$S19,1,0) -> 1 | G19: 18 | H19: 0.048999999 | I19: =(G19-$S19)/$S19 -> 0 | J19: =IF(G19=$S19,1,0) -> 1 | K19: 18 | L19: 9.2220001 | M19: =(K19-$S19)/$S19 -> 0 | N19: =IF(K19=$S19,1,0) -> 1 | S19: =MIN(C19,G19,K19) -> 18
B20: fs_541_2.mtx | C20: 3 | D20: 0.001 | E20: =(C20-$S20)/$S20 -> 0 | F20: =IF(C20=$S20,1,0) -> 1 | G20: 3 | H20: 0.026000001 | I20: =(G20-$S20)/$S20 -> 0 | J20: =IF(G20=$S20,1,0) -> 1 | K20: 3 | L20: 12.699 | M20: =(K20-$S20)/$S20 -> 0 | N20: =IF(K20=$S20,1,0) -> 1 | S20: =MIN(C20,G20,K20) -> 3
... B34: will199.mtx | C34: 112 | D34: 0 | E34: =(C34-$S34)/$S34 -> 0.17894737 | F34: =IF(C34=$S34,1,0) -> 0 | G34: 105 | H34: 0.0020000001 | I34: =(G34-$S34)/$S34 -> 0.10526316 | J34: =IF(G34=$S34,1,0) -> 0 | K34: 95 | L34: 0.178 | M34: =(K34-$S34)/$S34 -> 0 | N34: =IF(K34=$S34,1,0) -> 1 | S34: =MIN(C34,G34,K34) -> 95

Sheet Table 5
B2: Algorithm | C2: Avg. | D2: Time | E2: Dev. | F2: #best
B3: =C7 -> Variable Neighborhood Search | C3: =AVERAGE(C9:C34) -> 159.03846 | D3: =AVERAGE(D9:D34) -> 8.1656923 | E3: =AVERAGE(E9:E34) -> 0.014633192 | F3: =SUM(F9:F34) -> 15
B4: =G7 -> Tabu Search | C4: =AVERAGE(G9:G34) -> 155.73077 | D4: =AVERAGE(H9:H34) -> 4.1161154 | E4: =AVERAGE(I9:I34) -> 0.0064735899 | F4: =SUM(J9:J34) -> 19
B5: =K7 -> Iterated Local Search | C5: =AVERAGE(K9:K34) -> 154.30769 | D5: =AVERAGE(L9:L34) -> 5.6006923 | E5: =AVERAGE(M9:M34) -> 0.0033977862 | F5: =SUM(N9:N34) -> 24
C7: Variable Neighborhood Search | G7: Tabu Search | K7: Iterated Local Search
B8: Instance | C8: OF | D8: Time | E8: Dev | F8: Best | G8: OF | H8: Time | I8: Dev | J8: Best | K8: OF | L8: Time | M8: Dev | N8: Best | S8: #best
B9: 662_bus.mtx | C9: 538 | D9: 2.079 | E9: =(C9-$S9)/$S9 -> 0.011278195 | F9: =IF(C9=$S9,1,0) -> 0 | G9: 536 | H9: 2.043 | I9: =(G9-$S9)/$S9 -> 0.007518797 | J9: =IF(G9=$S9,1,0) -> 0 | K9: 532 | L9: 1.704 | M9: =(K9-$S9)/$S9 -> 0 | N9: =IF(K9=$S9,1,0) -> 1 | S9: =MIN(C9,G9,K9) -> 532
B10: ash331.mtx | C10: 161 | D10: 0.377 | E10: =(C10-$S10)/$S10 -> 0 | F10: =IF(C10=$S10,1,0) -> 1 | G10: 161 | H10: 0.215 | I10: =(G10-$S10)/$S10 -> 0 | J10: =IF(G10=$S10,1,0) -> 1 | K10: 161 | L10: 0.16500001 | M10: =(K10-$S10)/$S10 -> 0 | N10: =IF(K10=$S10,1,0) -> 1 | S10: =MIN(C10,G10,K10) -> 161
B11: bcspwr04.mtx | C11: 182 | D11: 0.94700003 | E11: =(C11-$S11)/$S11 -> 0.011111111 | F11: =IF(C11=$S11,1,0) -> 0 | G11: 180 | H11: 0.384 | I11: =(G11-$S11)/$S11 -> 0 | J11: =IF(G11=$S11,1,0) -> 1 | K11: 180 | L11: 0.35600001 | M11: =(K11-$S11)/$S11 -> 0 | N11: =IF(K11=$S11,1,0) -> 1 | S11: =MIN(C11,G11,K11) -> 180
B12: bcsstk01.mtx | C12: 18 | D12: 0.035 | E12: =(C12-$S12)/$S12 -> 0 | F12: =IF(C12=$S12,1,0) -> 1 | G12: 18 | H12: 0.012 | I12: =(G12-$S12)/$S12 -> 0 | J12: =IF(G12=$S12,1,0) -> 1 | K12: 18 | L12: 0.015 | M12: =(K12-$S12)/$S12 -> 0 | N12: =IF(K12=$S12,1,0) -> 1 | S12: =MIN(C12,G12,K12) -> 18
B13: bp_0.mtx | C13: 333 | D13: 23.162001 | E13: =(C13-$S13)/$S13 -> 0 | F13: =IF(C13=$S13,1,0) -> 1 | G13: 333 | H13: 10.381 | I13: =(G13-$S13)/$S13 -> 0 | J13: =IF(G13=$S13,1,0) -> 1 | K13: 333 | L13: 11.929 | M13: =(K13-$S13)/$S13 -> 0 | N13: =IF(K13=$S13,1,0) -> 1 | S13: =MIN(C13,G13,K13) -> 333
B14: can_161.mtx | C14: 57 | D14: 0.134 | E14: =(C14-$S14)/$S14 -> 0 | F14: =IF(C14=$S14,1,0) -> 1 | G14: 57 | H14: 0.064999998 | I14: =(G14-$S14)/$S14 -> 0 | J14: =IF(G14=$S14,1,0) -> 1 | K14: 57 | L14: 0.064000003 | M14: =(K14-$S14)/$S14 -> 0 | N14: =IF(K14=$S14,1,0) -> 1 | S14: =MIN(C14,G14,K14) -> 57
B15: cavity03.mtx | C15: 26 | D15: 9.7539997 | E15: =(C15-$S15)/$S15 -> 0 | F15: =IF(C15=$S15,1,0) -> 1 | G15: 26 | H15: 4.6479998 | I15: =(G15-$S15)/$S15 -> 0 | J15: =IF(G15=$S15,1,0) -> 1 | K15: 26 | L15: 4.698 | M15: =(K15-$S15)/$S15 -> 0 | N15: =IF(K15=$S15,1,0) -> 1 | S15: =MIN(C15,G15,K15) -> 26
B16: ck656.mtx | C16: 300 | D16: 48.472 | E16: =(C16-$S16)/$S16 -> 0.02739726 | F16: =IF(C16=$S16,1,0) -> 0 | G16: 297 | H16: 17.819 | I16: =(G16-$S16)/$S16 -> 0.017123288 | J16: =IF(G16=$S16,1,0) -> 0 | K16: 292 | L16: 36.973 | M16: =(K16-$S16)/$S16 -> 0 | N16: =IF(K16=$S16,1,0) -> 1 | S16: =MIN(C16,G16,K16) -> 292
B17: dwt_361.mtx | C17: 152 | D17: 1.0700001 | E17: =(C17-$S17)/$S17 -> 0.020134228 | F17: =IF(C17=$S17,1,0) -> 0 | G17: 149 | H17: 0.55699998 | I17: =(G17-$S17)/$S17 -> 0 | J17: =IF(G17=$S17,1,0) -> 1 | K17: 149 | L17: 0.43900001 | M17: =(K17-$S17)/$S17 -> 0 | N17: =IF(K17=$S17,1,0) -> 1 | S17: =MIN(C17,G17,K17) -> 149
B18: dwt_59.mtx | C18: 43 | D18: 0.013 | E18: =(C18-$S18)/$S18 -> 0 | F18: =IF(C18=$S18,1,0) -> 1 | G18: 43 | H18: 0.0049999999 | I18: =(G18-$S18)/$S18 -> 0 | J18: =IF(G18=$S18,1,0) -> 1 | K18: 43 | L18: 0.0049999999 | M18: =(K18-$S18)/$S18 -> 0 | N18: =IF(K18=$S18,1,0) -> 1 | S18: =MIN(C18,G18,K18) -> 43
B19: e05r0200.mtx | C19: 18 | D19: 18.365 | E19: =(C19-$S19)/$S19 -> 0 | F19: =IF(C19=$S19,1,0) -> 1 | G19: 18 | H19: 9.3070002 | I19: =(G19-$S19)/$S19 -> 0 | J19: =IF(G19=$S19,1,0) -> 1 | K19: 18 | L19: 9.2220001 | M19: =(K19-$S19)/$S19 -> 0 | N19: =IF(K19=$S19,1,0) -> 1 | S19: =MIN(C19,G19,K19) -> 18
B20: fs_541_2.mtx | C20: 3 | D20: 31.017 | E20: =(C20-$S20)/$S20 -> 0 | F20: =IF(C20=$S20,1,0) -> 1 | G20: 3 | H20: 13.275 | I20: =(G20-$S20)/$S20 -> 0 | J20: =IF(G20=$S20,1,0) -> 1 | K20: 3 | L20: 12.699 | M20: =(K20-$S20)/$S20 -> 0 | N20: =IF(K20=$S20,1,0) -> 1 | S20: =MIN(C20,G20,K20) -> 3
... B34: will199.mtx | C34: 92 | D34: 0.285 | E34: =(C34-$S34)/$S34 -> 0.022222222 | F34: =IF(C34=$S34,1,0) -> 0 | G34: 90 | H34: 0.38100001 | I34: =(G34-$S34)/$S34 -> 0 | J34: =IF(G34=$S34,1,0) -> 1 | K34: 95 | L34: 0.178 | M34: =(K34-$S34)/$S34 -> 0.055555556 | N34: =IF(K34=$S34,1,0) -> 0 | S34: =MIN(C34,G34,K34) -> 90

Sheet Table 6
D2: Algorithm | E2: Avg. | F2: Time | G2: Dev. | H2: #best
D3: =E9 -> Gc | E3: =AVERAGE(E11:E128) -> 264.52137 | F3: =AVERAGE(F11:F128) -> 0.00040170942 | G3: =AVERAGE(G11:G128) -> 0.024172113 | H3: =SUM(H11:H128) -> 64
D4: =I9 -> Gd | E4: =AVERAGE(I11:I128) -> 262.46154 | F4: =AVERAGE(J11:J128) -> 0.00065811968 | G4: =AVERAGE(K11:K128) -> 0.016521811 | H4: =SUM(L11:L128) -> 80
